Workbook
Name 부문: 'Raw(품의)'!$AF$1:$AF$4
Name 부문: '[1]Raw(품의)'!$AF$1:$AF$4
Name 부문: '[1]Raw(품의)'!$AF$1:$AF$4
Name 부문: '[1]Raw(품의)'!$AF$1:$AF$4

Sheet (신규) Summary
B4: 부문 | C4: 1 | J4: 2 | R4: 3 | Z4: 4
C5: 예산 | D5: 사용 | E5: 계획(사용 예정) | H5: 잔여 | J5: 예산 | L5: 사용 | M5: 계획 | P5: 잔여 | R5: 예산 | T5: 사용 | U5: 계획 | X5: 잔여 | Z5: 예산 | AB5: 사용 | AC5: 계획 | AF5: 잔여
E6: 품의 후 | F6: 품의 전 | G6: 소계 | H6: 사용 대비 | I6: 계획 포함 | J6: 예산 | K6: 전분기 포함 | M6: 품의 후 | N6: 품의 전 | O6: 소계 | P6: 사용 대비 | Q6: 계획 포함 | R6: 예산 | S6: 전분기 포함 | U6: 품의 후 | V6: 품의 전 | W6: 소계 | X6: 사용 대비 | Y6: 계획 포함 | Z6: 예산 | AA6: 전분기 포함 | AC6: 품의 후 | AD6: 품의 전 | AE6: 소계 | AF6: 사용 대비 | AG6: 계획 포함
B7: 제조DX솔루션 | C7: =SUMPRODUCT((예산!$B$3:$B$6='(신규) Summary'!$B7)*(예산!$C$2:$F$2='(신규) Summary'!C$4)*(예산!$C$3:$F$6)) | D7: =SUMPRODUCT(('집행(ERS)'!$B$3:$B$493='(신규) Summary'!C$4)*('집행(ERS)'!$C$3:$C$493='(신규) Summary'!$B7)*('집행(ERS)'!$J$3:$J$493)) | E7: =SUMPRODUCT(('Raw(품의)'!$B$5:$B$245='(신규) Summary'!C$4)*('Raw(품의)'!$E$5:$E$245='(신규) Summary'!$B7)*('Raw(품의)'!$Y$5:$Y$245=2)*('Raw(품의)'!$V$5:$V$245)) | F7: {=SUMPRODUCT(('26년 계획(품의전)'!$B$14:$B$418='(신규) Summary'!$B7)*('26년 계획(품의전)'!$E$14:$F$418='(신규) Summary'!C$4)*('26년 계획(품의전)'!$Z$14:$Z$418=2)*('26년 계획(품의전)'!$X$14:$Y$418))} | G7: =SUM(E7:F7) | H7: =C7-D7 | I7: =C7-D7-G7 | J7: =SUMPRODUCT((예산!$B$3:$B$6='(신규) Summary'!$B7)*(예산!$C$2:$F$2='(신규) Summary'!J$4)*(예산!$C$3:$F$6)) | K7: =I7+J7 | L7: =SUMPRODUCT(('집행(ERS)'!$B$3:$B$493='(신규) Summary'!J$4)*('집행(ERS)'!$C$3:$C$493='(신규) Summary'!$B7)*('집행(ERS)'!$J$3:$J$493)) | M7: =SUMPRODUCT(('Raw(품의)'!$B$5:$B$245='(신규) Summary'!J$4)*('Raw(품의)'!$E$5:$E$245='(신규) Summary'!$B7)*('Raw(품의)'!$Y$5:$Y$245=2)*('Raw(품의)'!$V$5:$V$245)) | N7: =SUMPRODUCT(('26년 계획(품의전)'!$B$14:$B$418='(신규) Summary'!$B7)*('26년 계획(품의전)'!$E$14:$F$418='(신규) Summary'!J$4)*('26년 계획(품의전)'!$Z$14:$Z$418=2)*('26년 계획(품의전)'!$X$14:$Y$418)) | O7: =SUM(M7:N7) | P7: =K7-L7 | Q7: =K7-L7-O7 | R7: =SUMPRODUCT((예산!$B$3:$B$6='(신규) Summary'!$B7)*(예산!$C$2:$F$2='(신규) Summary'!R$4)*(예산!$C$3:$F$6)) | S7: =Q7+R7 | T7: =SUMPRODUCT(('집행(ERS)'!$B$3:$B$495='(신규) Summary'!R$4)*('집행(ERS)'!$C$3:$C$495='(신규) Summary'!$B7)*('집행(ERS)'!$J$3:$J$495)) | U7: =SUMPRODUCT(('Raw(품의)'!$B$5:$B$251='(신규) Summary'!R$4)*('Raw(품의)'!$E$5:$E$251='(신규) Summary'!$B7)*('Raw(품의)'!$Y$5:$Y$251=2)*('Raw(품의)'!$V$5:$V$251)) | V7: =SUMPRODUCT(('26년 계획(품의전)'!$B$14:$B$418='(신규) Summary'!$B7)*('26년 계획(품의전)'!$E$14:$F$418='(신규) Summary'!R$4)*('26년 계획(품의전)'!$Z$14:$Z$418=2)*('26년 계획(품의전)'!$X$14:$Y$418)) | W7: =SUM(U7:V7) | X7: =S7-T7 | Y7: =S7-T7-W7 | Z7: =SUMPRODUCT((예산!$B$3:$B$6='(신규) Summary'!$B7)*(예산!$C$2:$F$2='(신규) Summary'!Z$4)*(예산!$C$3:$F$6)) | AA7: =Y7+Z7 | AB7: =SUMPRODUCT(('집행(ERS)'!$B$3:$B$495='(신규) Summary'!Z$4)*('집행(ERS)'!$C$3:$C$495='(신규) Summary'!$B7)*('집행(ERS)'!$J$3:$J$495)) | AC7: =SUMPRODUCT(('Raw(품의)'!$B$5:$B$251='(신규) Summary'!Z$4)*('Raw(품의)'!$E$5:$E$251='(신규) Summary'!$B7)*('Raw(품의)'!$Y$5:$Y$251=2)*('Raw(품의)'!$V$5:$V$251)) | AD7: =SUMPRODUCT(('26년 계획(품의전)'!$B$14:$B$418='(신규) Summary'!$B7)*('26년 계획(품의전)'!$E$14:$F$418='(신규) Summary'!Z$4)*('26년 계획(품의전)'!$Z$14:$Z$418=2)*('26년 계획(품의전)'!$X$14:$Y$418)) | AE7: =SUM(AC7:AD7) | AF7: =AA7-AB7 | AG7: =AA7-AB7-AE7
B8: 자동보정 | C8: =SUMPRODUCT((예산!$B$3:$B$6='(신규) Summary'!$B8)*(예산!$C$2:$F$2='(신규) Summary'!C$4)*(예산!$C$3:$F$6)) | D8: =SUMPRODUCT(('집행(ERS)'!$B$3:$B$493='(신규) Summary'!C$4)*('집행(ERS)'!$C$3:$C$493='(신규) Summary'!$B8)*('집행(ERS)'!$J$3:$J$493)) | E8: =SUMPRODUCT(('Raw(품의)'!$B$5:$B$245='(신규) Summary'!C$4)*('Raw(품의)'!$E$5:$E$245='(신규) Summary'!$B8)*('Raw(품의)'!$Y$5:$Y$245=2)*('Raw(품의)'!$V$5:$V$245)) | F8: {=SUMPRODUCT(('26년 계획(품의전)'!$B$14:$B$418='(신규) Summary'!$B8)*('26년 계획(품의전)'!$E$14:$F$418='(신규) Summary'!C$4)*('26년 계획(품의전)'!$Z$14:$Z$418=2)*('26년 계획(품의전)'!$X$14:$Y$418))} | G8: =SUM(E8:F8) | H8: =C8-D8 | I8: =C8-D8-G8 | J8: =SUMPRODUCT((예산!$B$3:$B$6='(신규) Summary'!$B8)*(예산!$C$2:$F$2='(신규) Summary'!J$4)*(예산!$C$3:$F$6)) | K8: =I8+J8 | L8: =SUMPRODUCT(('집행(ERS)'!$B$3:$B$493='(신규) Summary'!J$4)*('집행(ERS)'!$C$3:$C$493='(신규) Summary'!$B8)*('집행(ERS)'!$J$3:$J$493)) | M8: =SUMPRODUCT(('Raw(품의)'!$B$5:$B$245='(신규) Summary'!J$4)*('Raw(품의)'!$E$5:$E$245='(신규) Summary'!$B8)*('Raw(품의)'!$Y$5:$Y$245=2)*('Raw(품의)'!$V$5:$V$245)) | N8: =SUMPRODUCT(('26년 계획(품의전)'!$B$14:$B$418='(신규) Summary'!$B8)*('26년 계획(품의전)'!$E$14:$F$418='(신규) Summary'!J$4)*('26년 계획(품의전)'!$Z$14:$Z$418=2)*('26년 계획(품의전)'!$X$14:$Y$418)) | O8: =SUM(M8:N8) | P8: =K8-L8 | Q8: =K8-L8-O8 | R8: =SUMPRODUCT((예산!$B$3:$B$6='(신규) Summary'!$B8)*(예산!$C$2:$F$2='(신규) Summary'!R$4)*(예산!$C$3:$F$6)) | S8: =Q8+R8 | T8: =SUMPRODUCT(('집행(ERS)'!$B$3:$B$495='(신규) Summary'!R$4)*('집행(ERS)'!$C$3:$C$495='(신규) Summary'!$B8)*('집행(ERS)'!$J$3:$J$495)) | U8: =SUMPRODUCT(('Raw(품의)'!$B$5:$B$251='(신규) Summary'!R$4)*('Raw(품의)'!$E$5:$E$251='(신규) Summary'!$B8)*('Raw(품의)'!$Y$5:$Y$251=2)*('Raw(품의)'!$V$5:$V$251)) | V8: =SUMPRODUCT(('26년 계획(품의전)'!$B$14:$B$418='(신규) Summary'!$B8)*('26년 계획(품의전)'!$E$14:$F$418='(신규) Summary'!R$4)*('26년 계획(품의전)'!$Z$14:$Z$418=2)*('26년 계획(품의전)'!$X$14:$Y$418)) | W8: =SUM(U8:V8) | X8: =S8-T8 | Y8: =S8-T8-W8 | Z8: =SUMPRODUCT((예산!$B$3:$B$6='(신규) Summary'!$B8)*(예산!$C$2:$F$2='(신규) Summary'!Z$4)*(예산!$C$3:$F$6)) | AA8: =Y8+Z8 | AB8: =SUMPRODUCT(('집행(ERS)'!$B$3:$B$495='(신규) Summary'!Z$4)*('집행(ERS)'!$C$3:$C$495='(신규) Summary'!$B8)*('집행(ERS)'!$J$3:$J$495)) | AC8: =SUMPRODUCT(('Raw(품의)'!$B$5:$B$251='(신규) Summary'!Z$4)*('Raw(품의)'!$E$5:$E$251='(신규) Summary'!$B8)*('Raw(품의)'!$Y$5:$Y$251=2)*('Raw(품의)'!$V$5:$V$251)) | AD8: =SUMPRODUCT(('26년 계획(품의전)'!$B$14:$B$418='(신규) Summary'!$B8)*('26년 계획(품의전)'!$E$14:$F$418='(신규) Summary'!Z$4)*('26년 계획(품의전)'!$Z$14:$Z$418=2)*('26년 계획(품의전)'!$X$14:$Y$418)) | AE8: =SUM(AC8:AD8) | AF8: =AA8-AB8 | AG8: =AA8-AB8-AE8
B9: FDC DX | C9: =SUMPRODUCT((예산!$B$3:$B$6='(신규) Summary'!$B9)*(예산!$C$2:$F$2='(신규) Summary'!C$4)*(예산!$C$3:$F$6)) | D9: =SUMPRODUCT(('집행(ERS)'!$B$3:$B$493='(신규) Summary'!C$4)*('집행(ERS)'!$C$3:$C$493='(신규) Summary'!$B9)*('집행(ERS)'!$J$3:$J$493)) | E9: =SUMPRODUCT(('Raw(품의)'!$B$5:$B$245='(신규) Summary'!C$4)*('Raw(품의)'!$E$5:$E$245='(신규) Summary'!$B9)*('Raw(품의)'!$Y$5:$Y$245=2)*('Raw(품의)'!$V$5:$V$245)) | F9: {=SUMPRODUCT(('26년 계획(품의전)'!$B$14:$B$418='(신규) Summary'!$B9)*('26년 계획(품의전)'!$E$14:$F$418='(신규) Summary'!C$4)*('26년 계획(품의전)'!$Z$14:$Z$418=2)*('26년 계획(품의전)'!$X$14:$Y$418))} | G9: =SUM(E9:F9) | H9: =C9-D9 | I9: =C9-D9-G9 | J9: =SUMPRODUCT((예산!$B$3:$B$6='(신규) Summary'!$B9)*(예산!$C$2:$F$2='(신규) Summary'!J$4)*(예산!$C$3:$F$6)) | K9: =I9+J9 | L9: =SUMPRODUCT(('집행(ERS)'!$B$3:$B$493='(신규) Summary'!J$4)*('집행(ERS)'!$C$3:$C$493='(신규) Summary'!$B9)*('집행(ERS)'!$J$3:$J$493)) | M9: =SUMPRODUCT(('Raw(품의)'!$B$5:$B$245='(신규) Summary'!J$4)*('Raw(품의)'!$E$5:$E$245='(신규) Summary'!$B9)*('Raw(품의)'!$Y$5:$Y$245=2)*('Raw(품의)'!$V$5:$V$245)) | N9: {=SUMPRODUCT(('26년 계획(품의전)'!$B$14:$B$418='(신규) Summary'!$B9)*('26년 계획(품의전)'!$E$14:$F$418='(신규) Summary'!J$4)*('26년 계획(품의전)'!$Z$14:$Z$418=2)*('26년 계획(품의전)'!$X$14:$Y$418))} | O9: =SUM(M9:N9) | P9: =K9-L9 | Q9: =K9-L9-O9 | R9: =SUMPRODUCT((예산!$B$3:$B$6='(신규) Summary'!$B9)*(예산!$C$2:$F$2='(신규) Summary'!R$4)*(예산!$C$3:$F$6)) | S9: =Q9+R9 | T9: =SUMPRODUCT(('집행(ERS)'!$B$3:$B$495='(신규) Summary'!R$4)*('집행(ERS)'!$C$3:$C$495='(신규) Summary'!$B9)*('집행(ERS)'!$J$3:$J$495)) | U9: =SUMPRODUCT(('Raw(품의)'!$B$5:$B$251='(신규) Summary'!R$4)*('Raw(품의)'!$E$5:$E$251='(신규) Summary'!$B9)*('Raw(품의)'!$Y$5:$Y$251=2)*('Raw(품의)'!$V$5:$V$251)) | V9: =SUMPRODUCT(('26년 계획(품의전)'!$B$14:$B$418='(신규) Summary'!$B9)*('26년 계획(품의전)'!$E$14:$F$418='(신규) Summary'!R$4)*('26년 계획(품의전)'!$Z$14:$Z$418=2)*('26년 계획(품의전)'!$X$14:$Y$418)) | W9: =SUM(U9:V9) | X9: =S9-T9 | Y9: =S9-T9-W9 | Z9: =SUMPRODUCT((예산!$B$3:$B$6='(신규) Summary'!$B9)*(예산!$C$2:$F$2='(신규) Summary'!Z$4)*(예산!$C$3:$F$6)) | AA9: =Y9+Z9 | AB9: =SUMPRODUCT(('집행(ERS)'!$B$3:$B$495='(신규) Summary'!Z$4)*('집행(ERS)'!$C$3:$C$495='(신규) Summary'!$B9)*('집행(ERS)'!$J$3:$J$495)) | AC9: =SUMPRODUCT(('Raw(품의)'!$B$5:$B$251='(신규) Summary'!Z$4)*('Raw(품의)'!$E$5:$E$251='(신규) Summary'!$B9)*('Raw(품의)'!$Y$5:$Y$251=2)*('Raw(품의)'!$V$5:$V$251)) | AD9: =SUMPRODUCT(('26년 계획(품의전)'!$B$14:$B$418='(신규) Summary'!$B9)*('26년 계획(품의전)'!$E$14:$F$418='(신규) Summary'!Z$4)*('26년 계획(품의전)'!$Z$14:$Z$418=2)*('26년 계획(품의전)'!$X$14:$Y$418)) | AE9: =SUM(AC9:AD9) | AF9: =AA9-AB9 | AG9: =AA9-AB9-AE9
B10: 품질DX | C10: =SUMPRODUCT((예산!$B$3:$B$6='(신규) Summary'!$B10)*(예산!$C$2:$F$2='(신규) Summary'!C$4)*(예산!$C$3:$F$6)) | D10: =SUMPRODUCT(('집행(ERS)'!$B$3:$B$493='(신규) Summary'!C$4)*('집행(ERS)'!$C$3:$C$493='(신규) Summary'!$B10)*('집행(ERS)'!$J$3:$J$493)) | E10: =SUMPRODUCT(('Raw(품의)'!$B$5:$B$245='(신규) Summary'!C$4)*('Raw(품의)'!$E$5:$E$245='(신규) Summary'!$B10)*('Raw(품의)'!$Y$5:$Y$245=2)*('Raw(품의)'!$V$5:$V$245)) | F10: {=SUMPRODUCT(('26년 계획(품의전)'!$B$14:$B$418='(신규) Summary'!$B10)*('26년 계획(품의전)'!$E$14:$F$418='(신규) Summary'!C$4)*('26년 계획(품의전)'!$Z$14:$Z$418=2)*('26년 계획(품의전)'!$X$14:$Y$418))} | G10: =SUM(E10:F10) | H10: =C10-D10 | I10: =C10-D10-G10 | J10: =SUMPRODUCT((예산!$B$3:$B$6='(신규) Summary'!$B10)*(예산!$C$2:$F$2='(신규) Summary'!J$4)*(예산!$C$3:$F$6)) | K10: =I10+J10 | L10: =SUMPRODUCT(('집행(ERS)'!$B$3:$B$493='(신규) Summary'!J$4)*('집행(ERS)'!$C$3:$C$493='(신규) Summary'!$B10)*('집행(ERS)'!$J$3:$J$493)) | M10: =SUMPRODUCT(('Raw(품의)'!$B$5:$B$245='(신규) Summary'!J$4)*('Raw(품의)'!$E$5:$E$245='(신규) Summary'!$B10)*('Raw(품의)'!$Y$5:$Y$245=2)*('Raw(품의)'!$V$5:$V$245)) | N10: =SUMPRODUCT(('26년 계획(품의전)'!$B$14:$B$418='(신규) Summary'!$B10)*('26년 계획(품의전)'!$E$14:$F$418='(신규) Summary'!J$4)*('26년 계획(품의전)'!$Z$14:$Z$418=2)*('26년 계획(품의전)'!$X$14:$Y$418)) | O10: =SUM(M10:N10) | P10: =K10-L10 | Q10: =K10-L10-O10 | R10: =SUMPRODUCT((예산!$B$3:$B$6='(신규) Summary'!$B10)*(예산!$C$2:$F$2='(신규) Summary'!R$4)*(예산!$C$3:$F$6)) | S10: =Q10+R10 | T10: =SUMPRODUCT(('집행(ERS)'!$B$3:$B$495='(신규) Summary'!R$4)*('집행(ERS)'!$C$3:$C$495='(신규) Summary'!$B10)*('집행(ERS)'!$J$3:$J$495)) | U10: =SUMPRODUCT(('Raw(품의)'!$B$5:$B$251='(신규) Summary'!R$4)*('Raw(품의)'!$E$5:$E$251='(신규) Summary'!$B10)*('Raw(품의)'!$Y$5:$Y$251=2)*('Raw(품의)'!$V$5:$V$251)) | V10: =SUMPRODUCT(('26년 계획(품의전)'!$B$14:$B$418='(신규) Summary'!$B10)*('26년 계획(품의전)'!$E$14:$F$418='(신규) Summary'!R$4)*('26년 계획(품의전)'!$Z$14:$Z$418=2)*('26년 계획(품의전)'!$X$14:$Y$418)) | W10: =SUM(U10:V10) | X10: =S10-T10 | Y10: =S10-T10-W10 | Z10: =SUMPRODUCT((예산!$B$3:$B$6='(신규) Summary'!$B10)*(예산!$C$2:$F$2='(신규) Summary'!Z$4)*(예산!$C$3:$F$6)) | AA10: =Y10+Z10 | AB10: =SUMPRODUCT(('집행(ERS)'!$B$3:$B$495='(신규) Summary'!Z$4)*('집행(ERS)'!$C$3:$C$495='(신규) Summary'!$B10)*('집행(ERS)'!$J$3:$J$495)) | AC10: =SUMPRODUCT(('Raw(품의)'!$B$5:$B$251='(신규) Summary'!Z$4)*('Raw(품의)'!$E$5:$E$251='(신규) Summary'!$B10)*('Raw(품의)'!$Y$5:$Y$251=2)*('Raw(품의)'!$V$5:$V$251)) | AD10: =SUMPRODUCT(('26년 계획(품의전)'!$B$14:$B$418='(신규) Summary'!$B10)*('26년 계획(품의전)'!$E$14:$F$418='(신규) Summary'!Z$4)*('26년 계획(품의전)'!$Z$14:$Z$418=2)*('26년 계획(품의전)'!$X$14:$Y$418)) | AE10: =SUM(AC10:AD10) | AF10: =AA10-AB10 | AG10: =AA10-AB10-AE10
B11: 제조DX그룹 | C11: =SUM(C7:C10) | D11: =SUM(D7:D10) | E11: =SUM(E7:E10) | F11: =SUM(F7:F10) | G11: =SUM(G7:G10) | H11: =SUM(H7:H10) | I11: =SUM(I7:I10) | J11: =SUM(J7:J10) | ... AG11: =SUM(AG7:AG10)

Sheet 집행(ERS)
B2: 분기 | C2: 부문 | D2: 품의서 번호 | E2: 품의서 제목 | F2: 숙박비 | G2: 교통비 | H2: 일당 | I2: 기타잡비 | J2: 합계 | K2: 비용 처리
B3: 1 | C3: FDC DX | D3: B2512190011 | E3: ESWA법인 '26년 DX 추진과제 FDC 운영 협의 및 신규과제 발굴 / 현장 VOE 청취를 위한 출장 건 (260124 ~ 260130 / 민경춘, 이현우) | F3: 1968134 | G3: 4465885 | H3: 893579 | I3: 88000 | J3: 3157198
B4: 1 | C4: 제조DX솔루션 | D4: B2512170010 | E4: [해외출장/ESWA] L&S 수율 개선 솔루션 개발을 위한 해외출장의 건 (출장자 : 박경찬 팀장, 김승필 책임, 윤병호 선임/ '26.01.02 ~ 01.31) | F4: 13255200 | G4: 10195593 | H4: 13822851 | I4: 155606 | J4: 18063150
B5: 1 | C5: 제조DX솔루션 | D5: B2601190019 | E5: [재품의] [해외출장/ESMI] ESMI 계측기 Cell ID 연동 대표 호기 적용을 위한 해외 출장의 건 (출장자 : 이성규 선임/ '26.01.03 ~ 26.01.19 → 26.01.03 ~ 26.01.30) | F5: 6737291 | G5: 5874841 | H5: 4047148 | I5: 64573 | J5: 9780749
B6: 1 | C6: FDC DX | E6: 담당님 국내출장 | J6: =10000+10910+7273+22200
B7: 1 | C7: 자동보정 | E7: 담당님 국내출장 | J7: 259400
B8: 1 | C8: FDC DX | D8: B2601130039 | E8: [해외출장, ESST] 롤프레스 단선 개선 협업 논의 및 코터 연결불량 loss 개선안 출장계획 | F8: 9289999 | G8: 6260996 | H8: 7764168 | I8: 4138965 | J8: =SUM(F8:I8)-409408
B9: 1 | C9: 자동보정 | D9: B2601130061 | E9: [해외출장/ESST] ESST 롤프레스 단선 Loss 감소를 통한 ESS 수율 개선 출장 계획 | F9: 9694199 | G9: 7777318 | H9: 7496412 | I9: 4529641 | J9: =SUM(F9:I9)-177298
B10: 1 | C10: FDC DX | D10: B2512180027 | E10: DX과제 신규 데이터 조기 안정화 및 현상 점검 | J10: 838148
B11: 1 | C11: 자동보정 | D11: B2601160044 | E11: ESWA 코드표준화 & 과검 이상감지 대표호기 적용 | F11: 6477098 | G11: 7039278 | H11: 7205974 | I11: =80133-9091+79000 | J11: =SUM(F11:I11)
B12: 1 | C12: 자동보정 | D12: B2601130078 | E12: 롤프레스/노칭 PD Loss 개선을 위한 자동보정 신규 개발 및 적용 출장 건 | F12: 15432785 | G12: 11144231 | H12: 16581657 | I12: 436258 | J12: 43594931
B13: 1 | C13: 제조DX솔루션 | D13: B2603040014 | E13: ESWA 수율 개선 현황 점검 및 워크샵 참석 | F13: 1131527 | G13: 8746737 | H13: 630602 | J13: =SUM(F13:I13)
B14: 1 | C14: FDC DX | D14: B2602110046 | E14: [품의서] [해외출장/ESWA] ESWA E77A NND 공정 수율 개선을 위한 해외 출장의 건 (* 출장자 : 김시호 책임, 감미론 선임 / '26.02.25 ~ '26.03.20) | F14: 7293791 | G14: 7062507 | H14: 7671312 | I14: 170036 | J14: 20471462
B15: 1 | C15: 제조DX솔루션 | D15: B2601280022 | E15: [해외출장] ESWA 셀 수율 안정화 지원 | F15: 27626479 | G15: 10199967 | H15: 26827315 | I15: 404299 | J15: =SUM(F15:I15)
B16: 1 | C16: 제조DX솔루션 | D16: B2603040054 | E16: [해외출장/ESWA] ESWA 셀 수율 안정화 지원의 건, 3/13~4/16, 최이범책임, 조은지선임, 최재호선임 | F16: 16155402 | G16: 12401747 | H16: 16109847 | I16: 276012 | J16: =SUM(F16:I16)
B17: 1 | C17: 자동보정 | D17: B2604020048 | E17: [재품의] [출장 연장: 복귀 기준 4/10 → 4/18] ESWA LAMI 공정 자동보정 파라미터 실시간 최적화 & 클러스터링 기반 재료교체 Y축 예측모델 적용 | F17: 12036991 | G17: 12735159 | H17: 11297816 | I17: 223908 | J17: =SUM(F17:I17)
B18: 1 | C18: 제조DX솔루션 | D18: B2603100041 | E18: [해외출장/ESMI Lansing] ESMI Lansing 셀수율 안정화 지원(임성묵 선임, 26.03.27 ~ 05.01) | J18: 75550114
B19: 2 | C19: FDC DX | D19: B2604090053 | E19: [품의서] NJ Winder DX과제 전호기 확대 양산 검증 운영을 위한 출장 계획서 | F19: 3221953 | G19: 2796855 | H19: 1870467 | I19: 137919 | J19: =SUM(F19:I19)
B20: 2 | C20: 품질DX | D20: B2605080050 | E20: [해외출장/중국 심천(CIBF)] 중국 국제 배터리 박람회 참석을 통한 제조 지능화 동향 파악 출장 | J20: 2756333
B21: 2 | C21: FDC DX | D21: B2604080008 | E21: [품의서][해외출장] ESMI 법인 모듈/팩 공정 DX 과제 수행 | F21: 5582509 | G21: 3736900 | H21: 4571275 | I21: 467610 | J21: 14358294
B22: 2 | C22: FDC DX | D22: B2604080022 | E22: ESMI L&S 수율 안정화 및 가동률 개선 지원 | J22: =32334517+160000
B23: 2 | C23: 자동보정 | D23: B2604090013 | E23: ESMI L&S 신규 자동보정 기술 5건 적용 및 전사 DX 과제 추진 가속화 | J23: 20867143
B24: 2 | C24: 품질DX | D24: B2605260050 | E24: Audi TMM | F24: 1180684 | G24: 6641094 | H24: 708279 | I24: 9000 | J24: =SUM(F24:I24)
B25: 2 | C25: 자동보정 | D25: B2605070002 | E25: 중국 법인 자동보정 활용률 제고 및 제조 지능화 동향 파악 출장 | J25: 8423391
B26: 2 | C26: FDC DX | D26: B2606080059 | E26: NJ Winder FDC 내재화 지원을 위한 긴급 출장 요청 대응 | F26: 1702118 | G26: 1620808 | H26: 1201477 | I26: 59340 | J26: 4583743
B27: 2 | C27: FDC DX | D27: B2605070048 | E27: ESWA법인 '26년 WA 롤프레스 단선 개선 과제 (전사DX과제 건) & 노칭 NG마킹 불량 개선(NND) | J27: 15529077
B28: 2 | C28: 품질DX | D28: B2605260038 | E28: [품의서] ESS Project 수행관련 북미 지역 ESVT 법인 주요 시스템 분석 및 PWS 사 IT 시스템 Pain points 점검을 위한 출장 件 | J28: 33616303

Sheet Raw(품의)
AF1: 제조DX솔루션
B2: 분기 | C2: 품의서 번호 | D2: 품의서 제목 | E2: 부문 | F2: 출장자 | G2: 출장 일정 | H2: 계획 비용 | W2: 비고 | Y2: 비용처리 완료 유/무 | AF2: 자동보정
H3: 숙박비 | I3: 교통비 | M3: 일당 | P3: 기타잡비 | T3: 법인 지원 비용 | V3: 합계 | AF3: FDC DX
I4: 항공비 | J4: 렌트비 | K4: 공항 이동비 | L4: 소계 | M4: 단기 | N4: 장기 | O4: 소계 | P4: 준비금 | Q4: 통신비 | R4: 기타 | S4: 소계 | T4: 지원비 | U4: Site | AF4: 품질DX
B5: 1 | C5: B2601130039 | D5: [해외출장, ESST] 롤프레스 단선 개선 협업 논의 및 코터 연결불량 loss 개선안 출장계획 | E5: FDC DX | F5: 홍준혁 | G5: 2026-01-20~2026-02-14 | H5: 4200000 | I5: 2400000 | K5: 100000 | L5: 2500000 | N5: 3867313 | O5: 3867313 | P5: 2450000 | Q5: 250000 | R5: 250000 | S5: 2950000 | V5: 13517313 | W5: 기타잡비 : 입국수수료 및 준비금 준비금 : visa 처리비($1400) 및 진단검사비 | Y5: 1
B6: 1 | C6: B2601130039 | D6: [해외출장, ESST] 롤프레스 단선 개선 협업 논의 및 코터 연결불량 loss 개선안 출장계획 | E6: FDC DX | F6: 이창성 | G6: 2026-01-20~2026-02-14 | H6: 4200000 | I6: 2400000 | J6: 2000000 | K6: 100000 | L6: 4500000 | N6: 3867313 | O6: 3867313 | P6: 2450000 | Q6: 250000 | R6: 250000 | S6: 2950000 | V6: 15517313 | W6: 기타잡비 : 입국수수료 및 준비금 준비금 : visa 처리비($1400) 및 진단검사비 | Y6: 1
B7: 1 | C7: B2601130078 | D7: 롤프레스/노칭 PD Loss 개선을 위한 자동보정 신규 개발 및 적용 출장 건 | E7: 자동보정 | F7: 정돈규 | G7: 2026-01-16 ~ 2026-02-20 | H7: 5500000 | I7: 2100000 | J7: 3600000 | K7: 200000 | L7: 5900000 | N7: 5504973 | O7: 5504973 | P7: 100000 | Q7: 250000 | R7: - | S7: 350000 | V7: 17254973 | Y7: 1
B8: 1 | C8: B2601130078 | D8: 롤프레스/노칭 PD Loss 개선을 위한 자동보정 신규 개발 및 적용 출장 건 | E8: 자동보정 | F8: 정대영 | G8: 2026-01-16 ~ 2026-02-20 | H8: 5500000 | I8: 2100000 | J8: - | K8: 200000 | L8: 2300000 | N8: 5504973 | O8: 5504973 | P8: 100000 | Q8: 250000 | R8: - | S8: 350000 | V8: 13654973 | Y8: 1
B9: 1 | C9: B2601130078 | D9: 롤프레스/노칭 PD Loss 개선을 위한 자동보정 신규 개발 및 적용 출장 건 | E9: 자동보정 | F9: 이상용 | G9: 2026-01-16 ~ 2026-02-20 | H9: 5500000 | I9: 2100000 | J9: - | K9: 200000 | L9: 2300000 | N9: 5504973 | O9: 5504973 | P9: 100000 | Q9: 250000 | R9: - | S9: 350000 | V9: 13654973 | Y9: 1
B10: 1 | C10: B2601130061 | D10: [해외출장/ESST] ESST 롤프레스 단선 Loss 감소를 통한 ESS 수율 개선 출장 계획 | E10: 자동보정 | F10: 박상하 | G10: 2026/01/21~2026/02/14 | H10: 4450000 | I10: 2000000 | J10: 0 | K10: 100000 | L10: =SUM(I10:K10) | N10: 3740000 | O10: =SUM(M10:N10) | P10: 2000000 | Q10: 50000 | R10: 400000 | S10: =SUM(P10:R10) | V10: =SUM(H10,S10,O10,L10)-T10 | Y10: 1
B11: 1 | C11: B2601130061 | D11: [해외출장/ESST] ESST 롤프레스 단선 Loss 감소를 통한 ESS 수율 개선 출장 계획 | E11: 자동보정 | F11: 박홍준 | G11: 2026/01/21~2026/02/14 | H11: 4450000 | I11: 2000000 | J11: 2850000 | K11: 100000 | L11: =SUM(I11:K11) | N11: 3740000 | O11: =SUM(M11:N11) | P11: 2000000 | Q11: 50000 | R11: 400000 | S11: =SUM(P11:R11) | V11: =SUM(H11,S11,O11,L11)-T11 | Y11: 1
B12: 1 | C12: B2601160044 | D12: ESWA 코드표준화 & 과검 이상감지 대표호기 적용 | E12: 자동보정 | F12: 박준오 | G12: 2026-01-23 ~ 2026-02-13 | H12: 3500000 | I12: 2000000 | J12: 2500000 | K12: 250000 | L12: =SUM(I12:K12) | N12: 3549702 | O12: =SUM(M12:N12) | P12: 250000 | S12: =SUM(P12:R12) | V12: =SUM(H12,S12,O12,L12)-T12 | Y12: 1
B13: 1 | C13: B2601160044 | D13: ESWA 코드표준화 & 과검 이상감지 대표호기 적용 | E13: 자동보정 | F13: 임형찬 | G13: 2026-01-23 ~ 2026-02-13 | H13: 3500000 | I13: 2000000 | K13: 250000 | L13: =SUM(I13:K13) | N13: 3549702 | O13: =SUM(M13:N13) | P13: 250000 | S13: =SUM(P13:R13) | V13: =SUM(H13,S13,O13,L13)-T13 | Y13: 1
B14: 1 | C14: B2601280022 | D14: [해외출장] ESWA 셀 수율 안정화 지원 | E14: 제조DX솔루션 | F14: 박위대 | G14: 2/6 ~ 3/13 | H14: 11500000 | I14: 1475000 | K14: 100000 | L14: =SUM(I14:K14) | N14: =5625000+5500000 | O14: =SUM(M14:N14) | Q14: 150000 | R14: 225000 | S14: =SUM(P14:R14) | V14: =SUM(H14,S14,O14,L14)-T14 | Y14: 1
B15: 1 | C15: B2601280022 | D15: [해외출장] ESWA 셀 수율 안정화 지원 | E15: 제조DX솔루션 | F15: 박태욱 | G15: 2/6 ~ 3/13 | H15: 5500000 | I15: 1375000 | J15: 5500000 | K15: 100000 | L15: =SUM(I15:K15) | N15: 5625000 | O15: =SUM(M15:N15) | Q15: 150000 | R15: 125000 | S15: =SUM(P15:R15) | V15: =SUM(H15,S15,O15,L15)-T15 | Y15: 1
B16: 1 | C16: B2601280022 | D16: [해외출장] ESWA 셀 수율 안정화 지원 | E16: 제조DX솔루션 | F16: 김종우 | G16: 2/6 ~ 3/13 | H16: 5500000 | I16: 1375000 | J16: 0 | K16: 100000 | L16: =SUM(I16:K16) | N16: 5625000 | O16: =SUM(M16:N16) | Q16: 150000 | R16: 125000 | S16: =SUM(P16:R16) | V16: =SUM(H16,S16,O16,L16)-T16 | Y16: 1
B17: 1 | C17: B2601280022 | D17: [해외출장] ESWA 셀 수율 안정화 지원 | E17: 제조DX솔루션 | F17: 이찬혁 | G17: 2/6 ~ 3/13 | H17: 5500000 | I17: 1375000 | J17: 0 | K17: 100000 | L17: =SUM(I17:K17) | N17: 5625000 | O17: =SUM(M17:N17) | Q17: 150000 | R17: 125000 | S17: =SUM(P17:R17) | V17: =SUM(H17,S17,O17,L17)-T17 | Y17: 1
B18: 1 | C18: B2602110046 | D18: [품의서] [해외출장/ESWA] ESWA E77A NND 공정 수율 개선을 위한 해외 출장의 건 (* 출장자 : 김시호 책임, 감미론 선임 / '26.02.25 ~ '26.03.20) | E18: FDC DX | F18: 감미론 | G18: 26.2.25 ~ 26.3.20 | H18: 3500000 | I18: 1650000 | J18: 3000000 | K18: 30000 | L18: =SUM(I18:K18) | N18: 3889094 | O18: =SUM(M18:N18) | P18: 9000 | Q18: 79000 | S18: =SUM(P18:R18) | V18: =SUM(H18,S18,O18,L18)-T18 | Y18: 1
B19: 1 | C19: B2602110046 | D19: [품의서] [해외출장/ESWA] ESWA E77A NND 공정 수율 개선을 위한 해외 출장의 건 (* 출장자 : 김시호 책임, 감미론 선임 / '26.02.25 ~ '26.03.20) | E19: FDC DX | F19: 김시호 | G19: 26.2.25 ~ 26.3.20 | H19: 3500000 | I19: 1650000 | K19: 30000 | L19: =SUM(I19:K19) | N19: 3889094 | O19: =SUM(M19:N19) | P19: 9000 | Q19: 79000 | S19: =SUM(P19:R19) | V19: =SUM(H19,S19,O19,L19)-T19 | Y19: 1
B20: 1 | C20: B2603040054 | D20: [품의서] [해외출장/ESWA] ESWA 셀 수율 안정화 지원의 건, 3/13~4/16, 최이범책임, 조은지선임, 최재호선임 | E20: 제조DX솔루션 | F20: 최이범, 조은지, 최재호 | G20: 26.3.13~26.4.16 | H20: 16500000 | I20: 7500000 | J20: 5500000 | K20: 500000 | L20: =SUM(I20:K20) | N20: 17000000 | O20: =SUM(M20:N20) | Q20: 500000 | R20: 500000 | S20: =SUM(P20:R20) | V20: =SUM(H20,S20,O20,L20)-T20 | Y20: 1
B21: 1 | C21: B2603060048 | D21: ESWA LAMI 공정 자동보정 파라미터 실시간 최적화 & 클러스터링 기반 재료교체 Y축 예측모델 적용 | E21: 자동보정 | F21: 최문석 | G21: 3/14~4/10 | H21: 3700000 | I21: 3800000 | J21: 3300000 | K21: 50000 | L21: =SUM(I21:K21) | M21: 0 | N21: 4400000 | O21: =SUM(M21:N21) | P21: 0 | Q21: 100000 | R21: 0 | S21: =SUM(P21:R21) | T21: 0 | V21: =SUM(H21,S21,O21,L21)-T21 | Y21: 1
B22: 1 | C22: B2603060048 | D22: ESWA LAMI 공정 자동보정 파라미터 실시간 최적화 & 클러스터링 기반 재료교체 Y축 예측모델 적용 | E22: 자동보정 | F22: 김태욱 | G22: 3/14~4/10 | H22: 3700000 | I22: 3800000 | J22: 0 | K22: 50000 | L22: =SUM(I22:K22) | M22: 0 | N22: 4400000 | O22: =SUM(M22:N22) | P22: 0 | Q22: 100000 | R22: 0 | S22: =SUM(P22:R22) | T22: 0 | V22: =SUM(H22,S22,O22,L22)-T22 | Y22: 1
B23: 1 | C23: B2603100041 | D23: [해외출장/ESMI Lansing] ESMI Lansing 셀수율 안정화 지원(임성묵 선임, 26.03.27 ~ 05.01) | E23: 제조DX솔루션 | F23: 임성묵 | G23: 3/27~5/1 | H23: 7838100 | I23: 2948800 | K23: 100000 | L23: =SUM(I23:K23) | N23: 5280809 | O23: =SUM(M23:N23) | Q23: 150000 | S23: =SUM(P23:R23) | V23: =SUM(H23,S23,O23,L23)-T23 | Y23: 1
B24: 1 | C24: B2603160047 | D24: [해외출장/ESMI Lansing] ESMI Lansing 셀수율 안정화 지원(강주예 사원, 26.03.27 ~ 05.01) | E24: 제조DX솔루션 | F24: 강주예 | G24: 3/27~5/1 | H24: 7838100 | I24: 2948800 | K24: 100000 | L24: =SUM(I24:K24) | N24: 5280809 | O24: =SUM(M24:N24) | Q24: 150000 | S24: =SUM(P24:R24) | V24: =SUM(H24,S24,O24,L24)-T24 | Y24: 1
B25: 1 | C25: B2603100032 | D25: [해외출장/ESMI Lansing] ESMI Lansing 셀수율 안정화 지원(서준효 책임, 26.03.27 ~ 05.01) | E25: 제조DX솔루션 | F25: 서준효 | G25: 3/27~5/1 | H25: 7838100 | I25: 2948800 | J25: 3810000 | K25: 100000 | L25: =SUM(I25:K25) | N25: 5280809 | O25: =SUM(M25:N25) | P25: 10000 | Q25: 150000 | R25: 200000 | S25: =SUM(P25:R25) | V25: =SUM(H25,S25,O25,L25)-T25 | W25: 준비금 : 국제면허증, 기타 : 유류비 | Y25: 1
B26: 1 | C26: B2603180065 | D26: [해외출장/ESMI Lansing] ESMI Lansing 셀수율 안정화 지원(유연택 담당, 26.03.27 ~ 04.24) | E26: 제조DX솔루션 | F26: 유연택 | G26: 4/1~5/1 | H26: =H25*(4/5) | I26: 4000000 | K26: 100000 | L26: =SUM(I26:K26) | N26: =N25*(4/5) | O26: =SUM(M26:N26) | Q26: 150000 | S26: =SUM(P26:R26) | V26: =SUM(H26,S26,O26,L26)-T26 | W26: 품의 상신 전 | Y26: 1
B27: 2 | C27: B2604080008 | D27: [품의서][해외출장] ESMI 법인 모듈/팩 공정 DX 과제 수행 | E27: FDC DX | F27: 박종찬 | G27: 2026-04-15 ~ 2026-05-15 | H27: 5797551 | I27: 3693500 | J27: 0 | K27: 0 | L27: =SUM(I27:K27) | M27: 0 | N27: 4655919 | O27: =SUM(M27:N27) | P27: 0 | Q27: 0 | R27: 0 | S27: =SUM(P27:R27) | T27: 0 | U27: 0 | V27: =SUM(H27,S27,O27,L27)-T27 | Y27: 1
B28: 2 | C28: B2604080022 | D28: [품의서] ESMI L&S 수율 안정화 및 가동률 개선 지원 | E28: FDC DX | F28: 곽인철 | G28: 4/15~5/15 | H28: 6000000 | I28: 4041300 | J28: - | K28: 50000 | L28: =SUM(I28:K28) | N28: 4654674 | O28: =SUM(M28:N28) | Q28: 100000 | S28: =SUM(P28:R28) | V28: =SUM(H28,S28,O28,L28)-T28 | Y28: 1
B29: 2 | C29: B2604080028 | D29: ESMI 법인LNS공정 수율 개선 지원 | E29: FDC DX | F29: 김병찬 사원 | G29: 04.15 ~ 05.15 | H29: 7000000 | I29: 4000000 | J29: 4000000 | K29: 200000 | L29: =SUM(I29:K29) | N29: 4700000 | O29: =SUM(M29:N29) | Q29: 200000 | R29: 300000 | S29: =SUM(P29:R29) | V29: =SUM(H29,S29,O29,L29)-T29 | Y29: 1
B30: 2 | C30: B2604090053 | D30: [품의서] NJ Winder DX과제 전호기 확대 양산 검증 운영을 위한 출장 계획서 | E30: FDC DX | F30: 진민기 | G30: 26.04.16 ~ 26.04.29 | H30: =100000*13 | I30: 829000 | J30: 0 | K30: 100000 | L30: =SUM(I30:K30) | M30: 2137643 | O30: =SUM(M30:N30) | Q30: 50000 | S30: =SUM(P30:R30) | V30: =SUM(H30,S30,O30,L30)-T30 | Y30: 1
B31: 2 | C31: B2604090053 | D31: [품의서] NJ Winder DX과제 전호기 확대 양산 검증 운영을 위한 출장 계획서 | E31: FDC DX | F31: 김재희 | G31: 26.04.16 ~ 26.04.29 | H31: =100000*13 | I31: 829000 | J31: 0 | K31: 100000 | L31: =SUM(I31:K31) | M31: 2137643 | O31: =SUM(M31:N31) | Q31: 50000 | S31: =SUM(P31:R31) | V31: =SUM(H31,S31,O31,L31)-T31 | Y31: 1
B32: 2 | C32: B2604090053 | D32: [품의서] NJ Winder DX과제 전호기 확대 양산 검증 운영을 위한 출장 계획서 | E32: FDC DX | F32: 안진운 | G32: 26.04.23 ~ 26.04.29 | H32: =100000*6 | I32: 829000 | J32: 0 | K32: 100000 | L32: =SUM(I32:K32) | M32: 1068821.5 | O32: =SUM(M32:N32) | Q32: 50000 | S32: =SUM(P32:R32) | V32: 2647822 | Y32: 1
B33: 2 | C33: B2604090013 | D33: ESMI L&S 신규 자동보정 기술 5건 적용 및 전사 DX 과제 추진 가속화 | E33: 자동보정 | F33: 이제희 | G33: 26.04.22~26.05.29 | H33: 6000000 | I33: 3542000 | J33: - | K33: 50000 | L33: =SUM(I33:K33) | M33: - | N33: 4576224 | O33: =SUM(M33:N33) | P33: - | Q33: 100000 | R33: - | S33: =SUM(P33:R33) | T33: 10000000 | U33: ESMI | V33: =SUM(H33,S33,O33,L33)-T33 | Y33: 1
B34: 2 | C34: B2604150062 | D34: ESMI L&S 신규 자동보정 기술 5건 적용 및 전사 DX 과제 추진 가속화 | E34: 자동보정 | F34: 이기홍 | G34: 26.04.22~26.05.29 | H34: 6000000 | I34: 3542000 | J34: 4500000 | K34: 50000 | L34: =SUM(I34:K34) | M34: - | N34: 4576224 | O34: =SUM(M34:N34) | P34: - | Q34: 100000 | R34: - | S34: =SUM(P34:R34) | T34: 10000000 | U34: ESMI | V34: =SUM(H34,S34,O34,L34)-T34 | Y34: 1
B35: 2 | C35: B2604150057 | D35: ESMI L&S 신규 자동보정 기술 5건 적용 및 전사 DX 과제 추진 가속화 | E35: 자동보정 | F35: 김형원 | G35: 26.04.22~26.05.29 | H35: 6000000 | I35: 3542000 | J35: - | K35: 50000 | L35: =SUM(I35:K35) | M35: - | N35: 4576224 | O35: =SUM(M35:N35) | P35: - | Q35: 100000 | R35: - | S35: =SUM(P35:R35) | T35: 10000000 | U35: ESMI | V35: =SUM(H35,S35,O35,L35)-T35 | Y35: 1
B36: 2 | C36: B2605080050 | D36: [해외출장/중국 심천(CIBF)] 중국 국제 배터리 박람회 참석을 통한 제조 지능화 동향 파악 출장 | E36: 품질DX | F36: 한성원 | G36: 2026/5/13~5/16 | H36: 600000 | I36: 1073400 | J36: - | K36: 50000 | L36: =SUM(I36:K36) | M36: 602280 | O36: =SUM(M36:N36) | P36: - | Q36: 70000 | R36: - | S36: =SUM(P36:R36) | V36: =SUM(H36,S36,O36,L36)-T36 | Y36: 1
B37: 2 | C37: B2605080050 | D37: [해외출장/중국 심천(CIBF)] 중국 국제 배터리 박람회 참석을 통한 제조 지능화 동향 파악 출장 | E37: 품질DX | F37: 김도원 | G37: 2026/5/13~5/16 | H37: 600000 | I37: 1073400 | J37: - | K37: 50000 | L37: =SUM(I37:K37) | M37: 602280 | O37: =SUM(M37:N37) | P37: - | Q37: 70000 | R37: - | S37: =SUM(P37:R37) | V37: =SUM(H37,S37,O37,L37)-T37 | Y37: 1
B38: 2 | C38: B2605270054 | D38: [품의서] ESS Project 수행관련 북미 지역 ESVT 법인 주요 시스템 분석 및 PWS 사 IT 시스템 Pain points 점검을 위한 출장 件 | E38: 품질DX | F38: 임국빈 | G38: 6/8~6/30 | H38: 5420000 | I38: 4947400 | J38: 3000000 | K38: 80000 | L38: =SUM(I38:K38) | N38: 3577941 | O38: =SUM(M38:N38) | P38: 9000 | Q38: 79000 | S38: =SUM(P38:R38) | V38: =SUM(H38,S38,O38,L38)-T38 | Y38: 1
B39: 2 | C39: B2605260038 | D39: [품의서] ESS Project 수행관련 북미 지역 ESVT 법인 주요 시스템 분석 및 PWS 사 IT 시스템 Pain points 점검을 위한 출장 件 | E39: 품질DX | F39: 김홍진 | G39: 6/8~6/30 | H39: 5420000 | I39: 4947400 | K39: 80000 | L39: =SUM(I39:K39) | N39: 3590767 | O39: =SUM(M39:N39) | P39: 9000 | Q39: 79000 | S39: =SUM(P39:R39) | V39: =SUM(H39,S39,O39,L39)-T39 | Y39: 1
B40: 2 | C40: B2606080059 | D40: NJ Winder FDC 내재화 지원을 위한 긴급 출장 요청 대응 | E40: FDC DX | F40: 진민기 | G40: 2026-06-11 ~ 2026-06-19 | H40: 800000 | I40: 704100 | K40: 60000 | L40: =SUM(I40:K40) | M40: 1446181 | O40: =SUM(M40:N40) | Q40: 50000 | S40: =SUM(P40:R40) | V40: =SUM(H40,S40,O40,L40)-T40 | Y40: 1
...

Sheet 26년 계획(품의전)
B2: ■ `26년 해외출장 계획 | M2: 부문 | N2: 26년
N3: 예산 | O3: 사용 | P3: 계획(사용 예정) | S3: 잔여
P4: 품의 후 | Q4: 품의 전 | R4: 소계 | S4: 사용 대비 | T4: 계획 포함
M5: 제조DX솔루션 | N5: =예산!G3 | O5: ='(신규) Summary'!D7+'(신규) Summary'!L7+'(신규) Summary'!T7+'(신규) Summary'!AB7 | P5: ='(신규) Summary'!E7+'(신규) Summary'!M7+'(신규) Summary'!U7+'(신규) Summary'!AC7 | Q5: ='(신규) Summary'!F7+'(신규) Summary'!N7+'(신규) Summary'!V7+'(신규) Summary'!AD7 | R5: =SUM(P5:Q5) | S5: =N5-O5 | T5: =N5-O5-R5 | V5: =N5-O5-P5
M6: 자동보정 | N6: =예산!G4 | O6: ='(신규) Summary'!D8+'(신규) Summary'!L8+'(신규) Summary'!T8+'(신규) Summary'!AB8 | P6: ='(신규) Summary'!E8+'(신규) Summary'!M8+'(신규) Summary'!U8+'(신규) Summary'!AC8 | Q6: ='(신규) Summary'!F8+'(신규) Summary'!N8+'(신규) Summary'!V8+'(신규) Summary'!AD8 | R6: =SUM(P6:Q6) | S6: =N6-O6 | T6: =N6-O6-R6
M7: FDC DX | N7: =예산!G5 | O7: ='(신규) Summary'!D9+'(신규) Summary'!L9+'(신규) Summary'!T9+'(신규) Summary'!AB9 | P7: ='(신규) Summary'!E9+'(신규) Summary'!M9+'(신규) Summary'!U9+'(신규) Summary'!AC9 | Q7: ='(신규) Summary'!F9+'(신규) Summary'!N9+'(신규) Summary'!V9+'(신규) Summary'!AD9 | R7: =SUM(P7:Q7) | S7: =N7-O7 | T7: =N7-O7-R7
M8: 품질DX | N8: =예산!G6 | O8: ='(신규) Summary'!D10+'(신규) Summary'!L10+'(신규) Summary'!T10+'(신규) Summary'!AB10 | P8: ='(신규) Summary'!E10+'(신규) Summary'!M10+'(신규) Summary'!U10+'(신규) Summary'!AC10 | Q8: ='(신규) Summary'!F10+'(신규) Summary'!N10+'(신규) Summary'!V10+'(신규) Summary'!AD10 | R8: =SUM(P8:Q8) | S8: =N8-O8 | T8: =N8-O8-R8
M9: 제조DX그룹 | N9: =SUM(N5:N8) | O9: =SUM(O5:O8) | P9: =SUM(P5:P8) | Q9: =SUM(Q5:Q8) | R9: =SUM(R5:R8) | S9: =SUM(S5:S8) | T9: =SUM(T5:T8)
E11: ↓ 숫자만 입력 | N11: 입력x | X11: =SUBTOTAL(9,X14:X117)
B12: 소속 | D12: 출장 목적 | E12: 분기 | F12: 출장 일정 | J12: 출장 국가 | K12: 숙식 제공 (Y/N) | L12: 출장 인원 | M12: 임원 여부 | N12: 단가 | Q12: 예상 비용 | T12: 합계 | V12: 법인 비용 지원 | X12: 최종 합계 | Z12: 품의 여부 | AB12: 품의서 번호
B13: 부문 | C13: 팀명 | F13: 출발일 | G13: 복귀일 | H13: 숙박일수 | I13: 출장일수 | M13: (Y/N) | N13: 교통비 | O13: 숙박비 | P13: 일당 | Q13: 교통비 | R13: 숙박비 | S13: 일당
B14: 품질DX | C14: 품질DX팀 | D14: ESS 외주(피플웍스) 내재화 검토 및 외주(세방) 품질 IT 개선 | E14: 4 | F14: 46311 | G14: 46325 | H14: =G14-F14 | I14: =H14+1 | J14: 미주 | K14: N | L14: 1 | M14: Y | N14: =IF(M14="Y",VLOOKUP(J14,'[2]참고. 출장비 단가'!$B$7:$F$13,2,FALSE),VLOOKUP(J14,'[2]참고. 출장비 단가'!$B$7:$F$13,3,FALSE)) | O14: =VLOOKUP($J14,'[2]참고. 출장비 단가'!$B$7:$F$13,4,FALSE) | P14: =VLOOKUP($J14,'[2]참고. 출장비 단가'!$B$7:$F$13,5,FALSE) | Q14: =N14*L14 | R14: =IF(K14="Y",0,H14*O14)*L14 | S14: =IF(I14<15,I14*(P14+'[2]참고. 출장비 단가'!$D$29)*L14,P14*L14*14+(I14-14)*L14*P14*0.8) | T14: =SUM(Q14:S14) | V14: 0 | X14: =T14-V14 | Z14: 2
B15: 품질DX | C15: 품질DX팀 | D15: ESS 외주(피플웍스) 내재화 검토 및 외주(세방) 품질 IT 개선 | E15: 4 | F15: 46311 | G15: 46325 | H15: =G15-F15 | I15: =H15+1 | J15: 미주 | K15: N | L15: 1 | M15: N | N15: =IF(M15="Y",VLOOKUP(J15,'[2]참고. 출장비 단가'!$B$7:$F$13,2,FALSE),VLOOKUP(J15,'[2]참고. 출장비 단가'!$B$7:$F$13,3,FALSE)) | O15: =VLOOKUP($J15,'[2]참고. 출장비 단가'!$B$7:$F$13,4,FALSE) | P15: =VLOOKUP($J15,'[2]참고. 출장비 단가'!$B$7:$F$13,5,FALSE) | Q15: =N15*L15 | R15: =IF(K15="Y",0,H15*O15)*L15 | S15: =IF(I15<15,I15*(P15+'[2]참고. 출장비 단가'!$D$29)*L15,P15*L15*14+(I15-14)*L15*P15*0.8) | T15: =SUM(Q15:S15) | V15: 0 | X15: =T15-V15 | Z15: 2
B16: 품질DX | C16: 품질DX팀 | D16: ESMI1 PDS 자동차 북미법인 확산 | E16: 4 | F16: 46297 | G16: 46325 | H16: =G16-F16 | I16: =H16+1 | J16: 미주 | K16: N | L16: 1 | M16: N | N16: =IF(M16="Y",VLOOKUP(J16,'[2]참고. 출장비 단가'!$B$7:$F$13,2,FALSE),VLOOKUP(J16,'[2]참고. 출장비 단가'!$B$7:$F$13,3,FALSE)) | O16: =VLOOKUP($J16,'[2]참고. 출장비 단가'!$B$7:$F$13,4,FALSE) | P16: =VLOOKUP($J16,'[2]참고. 출장비 단가'!$B$7:$F$13,5,FALSE) | Q16: =N16*L16 | R16: =IF(K16="Y",0,H16*O16)*L16 | S16: =IF(I16<15,I16*(P16+'[2]참고. 출장비 단가'!$D$29)*L16,P16*L16*14+(I16-14)*L16*P16*0.8) | T16: =SUM(Q16:S16) | V16: 14500000 | X16: =T16-V16 | Z16: 2
B17: 품질DX | C17: 품질DX팀 | D17: ESMI-LS PDS ESS/자동차 북미법인 확산 | E17: 4 | F17: 46297 | G17: 46325 | H17: =G17-F17 | I17: =H17+1 | J17: 미주 | K17: N | L17: 1 | M17: N | N17: =IF(M17="Y",VLOOKUP(J17,'[2]참고. 출장비 단가'!$B$7:$F$13,2,FALSE),VLOOKUP(J17,'[2]참고. 출장비 단가'!$B$7:$F$13,3,FALSE)) | O17: =VLOOKUP($J17,'[2]참고. 출장비 단가'!$B$7:$F$13,4,FALSE) | P17: =VLOOKUP($J17,'[2]참고. 출장비 단가'!$B$7:$F$13,5,FALSE) | Q17: =N17*L17 | R17: =IF(K17="Y",0,H17*O17)*L17 | S17: =IF(I17<15,I17*(P17+'[2]참고. 출장비 단가'!$D$29)*L17,P17*L17*14+(I17-14)*L17*P17*0.8) | T17: =SUM(Q17:S17) | V17: 14500000 | X17: =T17-V17 | Z17: 2
B18: 품질DX | C18: 품질DX팀 | D18: ESHG PDS 자동차 북미법인 확산 | E18: 4 | F18: 46297 | G18: 46325 | H18: =G18-F18 | I18: =H18+1 | J18: 미주 | K18: N | L18: 1 | M18: N | N18: =IF(M18="Y",VLOOKUP(J18,'[2]참고. 출장비 단가'!$B$7:$F$13,2,FALSE),VLOOKUP(J18,'[2]참고. 출장비 단가'!$B$7:$F$13,3,FALSE)) | O18: =VLOOKUP($J18,'[2]참고. 출장비 단가'!$B$7:$F$13,4,FALSE) | P18: =VLOOKUP($J18,'[2]참고. 출장비 단가'!$B$7:$F$13,5,FALSE) | Q18: =N18*L18 | R18: =IF(K18="Y",0,H18*O18)*L18 | S18: =IF(I18<15,I18*(P18+'[2]참고. 출장비 단가'!$D$29)*L18,P18*L18*14+(I18-14)*L18*P18*0.8) | T18: =SUM(Q18:S18) | V18: 14500000 | X18: =T18-V18 | Z18: 2
B19: 품질DX | C19: 설비DX팀 | D19: ESHM GDC 현지 교육 | E19: 3 | F19: 46272 | G19: 46285 | H19: =G19-F19 | I19: =H19+1 | J19: 인도네시아 | K19: N | L19: 1 | M19: N | N19: =IF(M19="Y",VLOOKUP(J19,'[2]참고. 출장비 단가'!$B$7:$F$13,2,FALSE),VLOOKUP(J19,'[2]참고. 출장비 단가'!$B$7:$F$13,3,FALSE)) | O19: =VLOOKUP($J19,'[2]참고. 출장비 단가'!$B$7:$F$13,4,FALSE) | P19: =VLOOKUP($J19,'[2]참고. 출장비 단가'!$B$7:$F$13,5,FALSE) | Q19: =N19*L19 | R19: =IF(K19="Y",0,H19*O19)*L19 | S19: =IF(I19<15,I19*(P19+'[2]참고. 출장비 단가'!$D$29)*L19,P19*L19*14+(I19-14)*L19*P19*0.8) | T19: =SUM(Q19:S19) | V19: 0 | X19: =T19-V19 | Z19: 2
B20: 품질DX | C20: 설비DX팀 | D20: ESWA 롤맵 2.0전환/Tagless 지원 | E20: 3 | F20: 46258 | G20: 46287 | H20: =G20-F20 | I20: =H20+1 | J20: 폴란드 | K20: N | L20: 2 | M20: N | N20: =IF(M20="Y",VLOOKUP(J20,'[2]참고. 출장비 단가'!$B$7:$F$13,2,FALSE),VLOOKUP(J20,'[2]참고. 출장비 단가'!$B$7:$F$13,3,FALSE)) | O20: =VLOOKUP($J20,'[2]참고. 출장비 단가'!$B$7:$F$13,4,FALSE) | P20: =VLOOKUP($J20,'[2]참고. 출장비 단가'!$B$7:$F$13,5,FALSE) | Q20: =N20*L20 | R20: =IF(K20="Y",0,H20*O20)*L20 | S20: =IF(I20<15,I20*(P20+'[2]참고. 출장비 단가'!$D$29)*L20,P20*L20*14+(I20-14)*L20*P20*0.8) | T20: =SUM(Q20:S20) | V20: 0 | X20: =T20-V20 | Z20: 2
B21: 품질DX | C21: 설비DX팀 | D21: ESMI 롤맵 고도화 기능 수평전개 | E21: 3 | F21: 46240 | G21: 46268 | H21: =G21-F21 | I21: =H21+1 | J21: 미주 | K21: N | L21: 2 | M21: N | N21: =IF(M21="Y",VLOOKUP(J21,'[2]참고. 출장비 단가'!$B$7:$F$13,2,FALSE),VLOOKUP(J21,'[2]참고. 출장비 단가'!$B$7:$F$13,3,FALSE)) | O21: =VLOOKUP($J21,'[2]참고. 출장비 단가'!$B$7:$F$13,4,FALSE) | P21: =VLOOKUP($J21,'[2]참고. 출장비 단가'!$B$7:$F$13,5,FALSE) | Q21: =N21*L21 | R21: =IF(K21="Y",0,H21*O21)*L21 | S21: =IF(I21<15,I21*(P21+'[2]참고. 출장비 단가'!$D$29)*L21,P21*L21*14+(I21-14)*L21*P21*0.8) | T21: =SUM(Q21:S21) | V21: =T21 | X21: =T21-V21 | Z21: 2
B22: 품질DX | C22: 설비DX팀 | D22: ESMI_LS 롤맵 각형 대표라인 전개 | E22: 4 | F22: 46357 | G22: 46379 | H22: =G22-F22 | I22: =H22+1 | J22: 미주 | K22: N | L22: 2 | M22: N | N22: =IF(M22="Y",VLOOKUP(J22,'[2]참고. 출장비 단가'!$B$7:$F$13,2,FALSE),VLOOKUP(J22,'[2]참고. 출장비 단가'!$B$7:$F$13,3,FALSE)) | O22: =VLOOKUP($J22,'[2]참고. 출장비 단가'!$B$7:$F$13,4,FALSE) | P22: =VLOOKUP($J22,'[2]참고. 출장비 단가'!$B$7:$F$13,5,FALSE) | Q22: =N22*L22 | R22: =IF(K22="Y",0,H22*O22)*L22 | S22: =IF(I22<15,I22*(P22+'[2]참고. 출장비 단가'!$D$29)*L22,P22*L22*14+(I22-14)*L22*P22*0.8) | T22: =SUM(Q22:S22) | V22: =T22 | X22: =T22-V22 | Z22: 2
B23: 품질DX | C23: 설비DX팀 | D23: 설비관리시스템(EMS) ESAZ 법인 확산 전개 | E23: 4 | F23: 46342 | G23: 46362 | H23: =G23-F23 | I23: =H23+1 | J23: 미주 | K23: N | L23: 2 | M23: N | N23: =IF(M23="Y",VLOOKUP(J23,'[2]참고. 출장비 단가'!$B$7:$F$13,2,FALSE),VLOOKUP(J23,'[2]참고. 출장비 단가'!$B$7:$F$13,3,FALSE)) | O23: =VLOOKUP($J23,'[2]참고. 출장비 단가'!$B$7:$F$13,4,FALSE) | P23: =VLOOKUP($J23,'[2]참고. 출장비 단가'!$B$7:$F$13,5,FALSE) | Q23: =N23*L23 | R23: =IF(K23="Y",0,H23*O23)*L23 | S23: =IF(I23<15,I23*(P23+'[2]참고. 출장비 단가'!$D$29)*L23,P23*L23*14+(I23-14)*L23*P23*0.8) | T23: =SUM(Q23:S23) | V23: =T23 | X23: =T23-V23 | Z23: 2
B24: 품질DX | C24: 설비DX팀 | D24: ESWA EMS BM AX 과제 현지 검증/테스트 | E24: 3 | F24: 46285 | G24: 46295 | H24: =G24-F24 | I24: =H24+1 | J24: 폴란드 | K24: N | L24: 1 | M24: N | N24: =IF(M24="Y",VLOOKUP(J24,'[2]참고. 출장비 단가'!$B$7:$F$13,2,FALSE),VLOOKUP(J24,'[2]참고. 출장비 단가'!$B$7:$F$13,3,FALSE)) | O24: =VLOOKUP($J24,'[2]참고. 출장비 단가'!$B$7:$F$13,4,FALSE) | P24: =VLOOKUP($J24,'[2]참고. 출장비 단가'!$B$7:$F$13,5,FALSE) | Q24: =N24*L24 | R24: =IF(K24="Y",0,H24*O24)*L24 | S24: =IF(I24<15,I24*(P24+'[2]참고. 출장비 단가'!$D$29)*L24,P24*L24*14+(I24-14)*L24*P24*0.8) | T24: =SUM(Q24:S24) | V24: 0 | X24: =T24-V24 | Z24: 2
B25: 품질DX | C25: 공정DX팀 | D25: ESAZ법인 MMA(DCS) 구축 | E25: 3 | F25: 46262 | G25: 46283 | H25: =G25-F25 | I25: =H25+1 | J25: 미주 | K25: N | L25: 1 | M25: N | N25: =IF(M25="Y",VLOOKUP(J25,'[2]참고. 출장비 단가'!$B$7:$F$13,2,FALSE),VLOOKUP(J25,'[2]참고. 출장비 단가'!$B$7:$F$13,3,FALSE)) | O25: =VLOOKUP($J25,'[2]참고. 출장비 단가'!$B$7:$F$13,4,FALSE) | P25: =VLOOKUP($J25,'[2]참고. 출장비 단가'!$B$7:$F$13,5,FALSE) | Q25: =N25*L25 | R25: =IF(K25="Y",0,H25*O25)*L25 | S25: =IF(I25<15,I25*(P25+'[2]참고. 출장비 단가'!$D$29)*L25,P25*L25*14+(I25-14)*L25*P25*0.8) | T25: =SUM(Q25:S25) | V25: 12260000 | X25: =T25-V25 | Z25: 2
B26: 품질DX | C26: 공정DX팀 | D26: ESMI, ESMI_L, ESOT 법인 eIoT → FDC 전환 | E26: 3 | F26: 46237 | G26: 46255 | H26: =G26-F26 | I26: =H26+1 | J26: 미주 | K26: N | L26: 1 | M26: N | N26: =IF(M26="Y",VLOOKUP(J26,'[2]참고. 출장비 단가'!$B$7:$F$13,2,FALSE),VLOOKUP(J26,'[2]참고. 출장비 단가'!$B$7:$F$13,3,FALSE)) | O26: =VLOOKUP($J26,'[2]참고. 출장비 단가'!$B$7:$F$13,4,FALSE) | P26: =VLOOKUP($J26,'[2]참고. 출장비 단가'!$B$7:$F$13,5,FALSE) | Q26: =N26*L26 | R26: =IF(K26="Y",0,H26*O26)*L26 | S26: =IF(I26<15,I26*(P26+'[2]참고. 출장비 단가'!$D$29)*L26,P26*L26*14+(I26-14)*L26*P26*0.8) | T26: =SUM(Q26:S26) | V26: 0 | X26: =T26-V26 | Z26: 2
B27: 품질DX | C27: 공정DX팀 | D27: ESHG, ESHD법인 eIoT → FDC 전환 | E27: 3 | F27: 46246 | G27: 46262 | H27: =G27-F27 | I27: =H27+1 | J27: 미주 | K27: N | L27: 1 | M27: N | N27: =IF(M27="Y",VLOOKUP(J27,'[2]참고. 출장비 단가'!$B$7:$F$13,2,FALSE),VLOOKUP(J27,'[2]참고. 출장비 단가'!$B$7:$F$13,3,FALSE)) | O27: =VLOOKUP($J27,'[2]참고. 출장비 단가'!$B$7:$F$13,4,FALSE) | P27: =VLOOKUP($J27,'[2]참고. 출장비 단가'!$B$7:$F$13,5,FALSE) | Q27: =N27*L27 | R27: =IF(K27="Y",0,H27*O27)*L27 | S27: =IF(I27<15,I27*(P27+'[2]참고. 출장비 단가'!$D$29)*L27,P27*L27*14+(I27-14)*L27*P27*0.8) | T27: =SUM(Q27:S27) | V27: 0 | X27: =T27-V27 | Z27: 2
B28: 품질DX | C28: 공정DX팀 | D28: ESGM1, ESGM2법인 eIoT → FDC 전환 | E28: 3 | F28: 46272 | G28: 46288 | H28: =G28-F28 | I28: =H28+1 | J28: 미주 | K28: N | L28: 1 | M28: N | N28: =IF(M28="Y",VLOOKUP(J28,'[2]참고. 출장비 단가'!$B$7:$F$13,2,FALSE),VLOOKUP(J28,'[2]참고. 출장비 단가'!$B$7:$F$13,3,FALSE)) | O28: =VLOOKUP($J28,'[2]참고. 출장비 단가'!$B$7:$F$13,4,FALSE) | P28: =VLOOKUP($J28,'[2]참고. 출장비 단가'!$B$7:$F$13,5,FALSE) | Q28: =N28*L28 | R28: =IF(K28="Y",0,H28*O28)*L28 | S28: =IF(I28<15,I28*(P28+'[2]참고. 출장비 단가'!$D$29)*L28,P28*L28*14+(I28-14)*L28*P28*0.8) | T28: =SUM(Q28:S28) | V28: 0 | X28: =T28-V28 | Z28: 2
B29: 품질DX | C29: 공정DX팀 | D29: ESHM법인 eIoT → FDC 전환 | E29: 3 | F29: 46265 | G29: 46269 | H29: =G29-F29 | I29: =H29+1 | J29: 인도네시아 | K29: N | L29: 1 | M29: N | N29: =IF(M29="Y",VLOOKUP(J29,'[2]참고. 출장비 단가'!$B$7:$F$13,2,FALSE),VLOOKUP(J29,'[2]참고. 출장비 단가'!$B$7:$F$13,3,FALSE)) | O29: =VLOOKUP($J29,'[2]참고. 출장비 단가'!$B$7:$F$13,4,FALSE) | P29: =VLOOKUP($J29,'[2]참고. 출장비 단가'!$B$7:$F$13,5,FALSE) | Q29: =N29*L29 | R29: =IF(K29="Y",0,H29*O29)*L29 | S29: =IF(I29<15,I29*(P29+'[2]참고. 출장비 단가'!$D$29)*L29,P29*L29*14+(I29-14)*L29*P29*0.8) | T29: =SUM(Q29:S29) | V29: 0 | X29: =T29-V29 | Z29: 2
B30: 품질DX | C30: 공정DX팀 | D30: ESWA법인 eIoT → FDC 전환 | E30: 3 | F30: 46279 | G30: 46297 | H30: =G30-F30 | I30: =H30+1 | J30: 폴란드 | K30: N | L30: 1 | M30: N | N30: =IF(M30="Y",VLOOKUP(J30,'[2]참고. 출장비 단가'!$B$7:$F$13,2,FALSE),VLOOKUP(J30,'[2]참고. 출장비 단가'!$B$7:$F$13,3,FALSE)) | O30: =VLOOKUP($J30,'[2]참고. 출장비 단가'!$B$7:$F$13,4,FALSE) | P30: =VLOOKUP($J30,'[2]참고. 출장비 단가'!$B$7:$F$13,5,FALSE) | Q30: =N30*L30 | R30: =IF(K30="Y",0,H30*O30)*L30 | S30: =IF(I30<15,I30*(P30+'[2]참고. 출장비 단가'!$D$29)*L30,P30*L30*14+(I30-14)*L30*P30*0.8) | T30: =SUM(Q30:S30) | V30: 0 | X30: =T30-V30 | Z30: 2
B31: 품질DX | C31: 공정DX팀 | D31: ESNJ, ESNB, ESNJ 법인 eIoT → FDC 전환 | E31: 3 | F31: 46280 | G31: 46310 | H31: =G31-F31 | I31: =H31+1 | J31: 중국 | K31: N | L31: 1 | M31: N | N31: =IF(M31="Y",VLOOKUP(J31,'[2]참고. 출장비 단가'!$B$7:$F$13,2,FALSE),VLOOKUP(J31,'[2]참고. 출장비 단가'!$B$7:$F$13,3,FALSE)) | O31: =VLOOKUP($J31,'[2]참고. 출장비 단가'!$B$7:$F$13,4,FALSE) | P31: =VLOOKUP($J31,'[2]참고. 출장비 단가'!$B$7:$F$13,5,FALSE) | Q31: =N31*L31 | R31: =IF(K31="Y",0,H31*O31)*L31 | S31: =IF(I31<15,I31*(P31+'[2]참고. 출장비 단가'!$D$29)*L31,P31*L31*14+(I31-14)*L31*P31*0.8) | T31: =SUM(Q31:S31) | V31: 0 | X31: =T31-V31 | Z31: 2
B32: 품질DX | C32: 공정DX팀 | D32: SW/MOD VCT 시스템 구축 | E32: 3 | F32: 46262 | G32: 46283 | H32: =G32-F32 | I32: =H32+1 | J32: 폴란드 | K32: N | L32: 1 | M32: N | N32: =IF(M32="Y",VLOOKUP(J32,'[2]참고. 출장비 단가'!$B$7:$F$13,2,FALSE),VLOOKUP(J32,'[2]참고. 출장비 단가'!$B$7:$F$13,3,FALSE)) | O32: =VLOOKUP($J32,'[2]참고. 출장비 단가'!$B$7:$F$13,4,FALSE) | P32: =VLOOKUP($J32,'[2]참고. 출장비 단가'!$B$7:$F$13,5,FALSE) | Q32: =N32*L32 | R32: =IF(K32="Y",0,H32*O32)*L32 | S32: =IF(I32<15,I32*(P32+'[2]참고. 출장비 단가'!$D$29)*L32,P32*L32*14+(I32-14)*L32*P32*0.8) | T32: =SUM(Q32:S32) | V32: 10710000 | X32: =T32-V32 | Z32: 2
B33: 품질DX | C33: 공정DX팀 | D33: ESWA SPC 노칭 Vision 기인 NG Cell 배출 기능 적용 | E33: 4 | F33: 46304 | G33: 46325 | H33: =G33-F33 | I33: =H33+1 | J33: 폴란드 | K33: N | L33: 1 | M33: N | N33: =IF(M33="Y",VLOOKUP(J33,'[2]참고. 출장비 단가'!$B$7:$F$13,2,FALSE),VLOOKUP(J33,'[2]참고. 출장비 단가'!$B$7:$F$13,3,FALSE)) | O33: =VLOOKUP($J33,'[2]참고. 출장비 단가'!$B$7:$F$13,4,FALSE) | P33: =VLOOKUP($J33,'[2]참고. 출장비 단가'!$B$7:$F$13,5,FALSE) | Q33: =N33*L33 | R33: =IF(K33="Y",0,H33*O33)*L33 | S33: =IF(I33<15,I33*(P33+'[2]참고. 출장비 단가'!$D$29)*L33,P33*L33*14+(I33-14)*L33*P33*0.8) | T33: =SUM(Q33:S33) | V33: 0 | X33: =T33-V33 | Z33: 2
B34: 품질DX | C34: 공정DX팀 | D34: ESAZ PDS-RMS 시스템 구축에 따른 RMS 대응 | E34: 4 | F34: 46297 | G34: 46318 | H34: =G34-F34 | I34: =H34+1 | J34: 미주 | K34: N | L34: 1 | M34: N | N34: =IF(M34="Y",VLOOKUP(J34,'[2]참고. 출장비 단가'!$B$7:$F$13,2,FALSE),VLOOKUP(J34,'[2]참고. 출장비 단가'!$B$7:$F$13,3,FALSE)) | O34: =VLOOKUP($J34,'[2]참고. 출장비 단가'!$B$7:$F$13,4,FALSE) | P34: =VLOOKUP($J34,'[2]참고. 출장비 단가'!$B$7:$F$13,5,FALSE) | Q34: =N34*L34 | R34: =IF(K34="Y",0,H34*O34)*L34 | S34: =IF(I34<15,I34*(P34+'[2]참고. 출장비 단가'!$D$29)*L34,P34*L34*14+(I34-14)*L34*P34*0.8) | T34: =SUM(Q34:S34) | V34: 12260000 | X34: =T34-V34 | Z34: 2
B35: 품질DX | C35: DAVINCI팀 | D35: AZ법인 다빈치 오픈 및 활성화 대응 | E35: 3 | F35: 46242 | G35: 46262 | H35: =G35-F35 | I35: =H35+1 | J35: 미주 | K35: N | L35: 1 | M35: N | N35: =IF(M35="Y",VLOOKUP(J35,'[2]참고. 출장비 단가'!$B$7:$F$13,2,FALSE),VLOOKUP(J35,'[2]참고. 출장비 단가'!$B$7:$F$13,3,FALSE)) | O35: =VLOOKUP($J35,'[2]참고. 출장비 단가'!$B$7:$F$13,4,FALSE) | P35: =VLOOKUP($J35,'[2]참고. 출장비 단가'!$B$7:$F$13,5,FALSE) | Q35: =N35*L35 | R35: =IF(K35="Y",0,H35*O35)*L35 | S35: =IF(I35<15,I35*(P35+'[2]참고. 출장비 단가'!$D$29)*L35,P35*L35*14+(I35-14)*L35*P35*0.8) | T35: =SUM(Q35:S35) | V35: 11940000 | X35: =T35-V35 | Z35: 2
B36: 품질DX | C36: DAVINCI팀 | D36: 북미 ESS생산 법인 워크플로우 활용 및 분석 지원(MI/MIL/HD) | E36: 4 | F36: 46301 | G36: 46331 | H36: =G36-F36 | I36: =H36+1 | J36: 미주 | K36: N | L36: 2 | M36: N | N36: =IF(M36="Y",VLOOKUP(J36,'[2]참고. 출장비 단가'!$B$7:$F$13,2,FALSE),VLOOKUP(J36,'[2]참고. 출장비 단가'!$B$7:$F$13,3,FALSE)) | O36: =VLOOKUP($J36,'[2]참고. 출장비 단가'!$B$7:$F$13,4,FALSE) | P36: =VLOOKUP($J36,'[2]참고. 출장비 단가'!$B$7:$F$13,5,FALSE) | Q36: =N36*L36 | R36: =IF(K36="Y",0,H36*O36)*L36 | S36: =IF(I36<15,I36*(P36+'[2]참고. 출장비 단가'!$D$29)*L36,P36*L36*14+(I36-14)*L36*P36*0.8) | T36: =SUM(Q36:S36) | V36: 0 | X36: =T36-V36 | Z36: 2
B37: 품질DX | C37: DAVINCI팀 | D37: 중국 법인 워크플로우 활용 및 Painpoint 개선(NB/NJ/NA) | E37: 3 | F37: 46272 | G37: 46300 | H37: =G37-F37 | I37: =H37+1 | J37: 중국 | K37: N | L37: 2 | M37: N | N37: =IF(M37="Y",VLOOKUP(J37,'[2]참고. 출장비 단가'!$B$7:$F$13,2,FALSE),VLOOKUP(J37,'[2]참고. 출장비 단가'!$B$7:$F$13,3,FALSE)) | O37: =VLOOKUP($J37,'[2]참고. 출장비 단가'!$B$7:$F$13,4,FALSE) | P37: =VLOOKUP($J37,'[2]참고. 출장비 단가'!$B$7:$F$13,5,FALSE) | Q37: =N37*L37 | R37: =IF(K37="Y",0,H37*O37)*L37 | S37: =IF(I37<15,I37*(P37+'[2]참고. 출장비 단가'!$D$29)*L37,P37*L37*14+(I37-14)*L37*P37*0.8) | T37: =SUM(Q37:S37) | V37: 0 | X37: =T37-V37 | Z37: 2
B38: 제조DX솔루션 | C38: 제조빅데이터분석1팀 | D38: ESWA법인 '26년 셀수율 안정화 | E38: 4 | F38: 46304 | G38: 46339 | H38: =G38-F38 | I38: =H38+1 | J38: 폴란드 | K38: N | L38: 3 | M38: N | N38: =IF(M38="Y",VLOOKUP(J38,'[2]참고. 출장비 단가'!$B$7:$F$13,2,FALSE),VLOOKUP(J38,'[2]참고. 출장비 단가'!$B$7:$F$13,3,FALSE)) | O38: =VLOOKUP($J38,'[2]참고. 출장비 단가'!$B$7:$F$13,4,FALSE) | P38: =VLOOKUP($J38,'[2]참고. 출장비 단가'!$B$7:$F$13,5,FALSE) | Q38: =N38*L38 | R38: =IF(K38="Y",0,H38*O38)*L38 | S38: =IF(I38<15,I38*(P38+'[2]참고. 출장비 단가'!$D$29)*L38,P38*L38*14+(I38-14)*L38*P38*0.8) | T38: =SUM(Q38:S38) | X38: =T38-V38 | Z38: 2
B39: 제조DX솔루션 | C39: 제조빅데이터분석1팀 | D39: ESWA법인 '26년 셀수율 안정화 | E39: 3 | F39: 46255 | G39: 46297 | H39: =G39-F39 | I39: =H39+1 | J39: 폴란드 | K39: N | L39: 3 | M39: N | N39: =IF(M39="Y",VLOOKUP(J39,'[2]참고. 출장비 단가'!$B$7:$F$13,2,FALSE),VLOOKUP(J39,'[2]참고. 출장비 단가'!$B$7:$F$13,3,FALSE)) | O39: =VLOOKUP($J39,'[2]참고. 출장비 단가'!$B$7:$F$13,4,FALSE) | P39: =VLOOKUP($J39,'[2]참고. 출장비 단가'!$B$7:$F$13,5,FALSE) | Q39: =N39*L39 | R39: =IF(K39="Y",0,H39*O39)*L39 | S39: =IF(I39<15,I39*(P39+'[2]참고. 출장비 단가'!$D$29)*L39,P39*L39*14+(I39-14)*L39*P39*0.8) | T39: =SUM(Q39:S39) | V39: 0 | X39: =T39-V39 | Z39: 2
B40: 제조DX솔루션 | C40: 제조빅데이터분석2팀 | D40: ESMI법인 '26년 셀수율 안정화 지원 | E40: 4 | F40: 46297 | G40: 46332 | H40: =G40-F40 | I40: =H40+1 | J40: 미주 | K40: N | L40: 2 | M40: N | N40: =IF(M40="Y",VLOOKUP(J40,'[2]참고. 출장비 단가'!$B$7:$F$13,2,FALSE),VLOOKUP(J40,'[2]참고. 출장비 단가'!$B$7:$F$13,3,FALSE)) | O40: =VLOOKUP($J40,'[2]참고. 출장비 단가'!$B$7:$F$13,4,FALSE) | P40: =VLOOKUP($J40,'[2]참고. 출장비 단가'!$B$7:$F$13,5,FALSE) | Q40: =N40*L40 | R40: =IF(K40="Y",0,H40*O40)*L40 | S40: =IF(I40<15,I40*(P40+'[2]참고. 출장비 단가'!$D$29)*L40,P40*L40*14+(I40-14)*L40*P40*0.8) | T40: =SUM(Q40:S40) | V40: 0 | X40: =T40-V40 | Z40: 2
B41: FDC DX | C41: 원통형조립FDC팀 | D41: ESAZ 양산 조기 안정화 지원 | E41: 4 | F41: 46327 | G41: 46356 | H41: =G41-F41 | I41: =H41+1 | J41: 미주 | K41: N | L41: 3 | M41: N | N41: =IF(M41="Y",VLOOKUP(J41,'[2]참고. 출장비 단가'!$B$7:$F$13,2,FALSE),VLOOKUP(J41,'[2]참고. 출장비 단가'!$B$7:$F$13,3,FALSE)) | O41: =VLOOKUP($J41,'[2]참고. 출장비 단가'!$B$7:$F$13,4,FALSE) | P41: =VLOOKUP($J41,'[2]참고. 출장비 단가'!$B$7:$F$13,5,FALSE) | Q41: =N41*L41 | R41: =IF(K41="Y",0,H41*O41)*L41 | S41: =IF(I41<15,I41*(P41+'[2]참고. 출장비 단가'!$D$29)*L41,P41*L41*14+(I41-14)*L41*P41*0.8) | T41: =SUM(Q41:S41) | V41: 0 | X41: =T41-V41 | Z41: 2
B42: FDC DX | C42: 원통형조립FDC팀 | D42: ESNJ법인 '26년 DX 추진과제 확대호기 양산 검증 운영 및 인프라 점검 | E42: 3 | F42: 46265 | G42: 46276 | H42: =G42-F42 | I42: =H42+1 | J42: 중국 | K42: N | L42: 2 | M42: N | N42: =IF(M42="Y",VLOOKUP(J42,'[2]참고. 출장비 단가'!$B$7:$F$13,2,FALSE),VLOOKUP(J42,'[2]참고. 출장비 단가'!$B$7:$F$13,3,FALSE)) | O42: =VLOOKUP($J42,'[2]참고. 출장비 단가'!$B$7:$F$13,4,FALSE) | P42: =VLOOKUP($J42,'[2]참고. 출장비 단가'!$B$7:$F$13,5,FALSE) | Q42: =N42*L42 | R42: =IF(K42="Y",0,H42*O42)*L42 | S42: =IF(I42<15,I42*(P42+'[2]참고. 출장비 단가'!$D$29)*L42,P42*L42*14+(I42-14)*L42*P42*0.8) | T42: =SUM(Q42:S42) | V42: 0 | X42: =T42-V42 | Z42: 2
...

Sheet 참고.출장비 단가
B2: ▶ 국내/해외출장 단가 책정안
F3: 일당 (식대, 현지교통비, 기타잡비)
B4: 출장 국가 | C4: 교통비 | E4: 숙박비 | F4: 일당
C5: 임원 | D5: 팀원/팀장
B6: 국내 | C6: 65000 | D6: 65000 | E6: 80000 | F6: 30000
B7: 미주 | C7: 10000000 | D7: 5000000 | E7: 200000 | F7: 150000
B8: 인도네시아 | C8: 5000000 | D8: 2500000 | E8: 80000 | F8: 150000
B9: 일본 | C9: 1000000 | D9: 1000000 | E9: 80000 | F9: 115000
B10: 중국 | C10: 1000000 | D10: 1000000 | E10: 80000 | F10: 105000
B11: 폴란드 | C11: 9000000 | D11: 4500000 | E11: 150000 | F11: 150000
B12: 호주 | C12: =D12*2 | D12: 2500000 | E12: 150000 | F12: 150000
B13: 유럽(폴란드 外) | C13: 9000000 | D13: 4500000 | E13: 150000 | F13: 150000
B14: 기타 | C14: 업무지원Portal - BTMS - 출장예약 참고
B18: ☞해외 출장 일당 단가 (23년 하반기 사업보고 환율 적용)
B20: ① 해외출장 일당 지급 한도액으로 일괄 적용 (단기/장기 구분 X)
C21: 현지화 | D21: 환율 | E21: 원화 금액
B22: 중국(RMB) | C22: 540 | D22: 178 | E22: =C22*D22
B23: 일본(100￥) | C23: 130 | D23: 921 | E23: =C23*D23
B24: 유로화(€) | C24: 100 | D24: 1373 | E24: =C24*D24
B25: 달러($) | C25: 110 | D25: 1240 | E25: =C25*D25
B27: ② 단기일당 추가 지급 반영
C28: 달러($) | D28: 원화 금액
B29: 1~14일 | C29: 20 | D29: =C29*$D$25

Sheet 예산
B2: 부문 | C2: 1 | D2: 2 | E2: 3 | F2: 4 | G2: 26년
B3: 제조DX솔루션 | C3: 75000000 | D3: =75000000+41000000+75000000 | E3: 0 | F3: 75000000 | G3: =SUM(C3:F3)
B4: 자동보정 | C4: 75000000 | D4: =75000000+11000000-6000000 | E4: 75000000 | F4: 75000000 | G4: =SUM(C4:F4)
B5: FDC DX | C5: 75000000 | D5: =75000000+33000000 | E5: 75000000 | F5: 75000000 | G5: =SUM(C5:F5)
B6: 품질DX | C6: =75000000-10000000 | D6: =75000000-85000000+75000000 | E6: 0 | F6: 75000000 | G6: =SUM(C6:F6)
C7: =SUM(C3:C6) | D7: =SUM(D3:D6) | E7: =SUM(E3:E6) | F7: =SUM(F3:F6) | G7: =SUM(G3:G6)
K15: s

Sheet 예상계획_로그
A1: 기준일 | B1: 팀 | C1: 출장자 | D1: 출장목적 | E1: 출발일 | F1: 귀국일 | G1: 금액(원) | H1: 비고
A2: 46227 | B2: 자동보정팀 | C2: 홍길동 | D2: 설비 협의 | E2: 46235 | F2: 46239 | G2: 3500000
A3: 46227 | B3: 자동보정팀 | C3: 김철수 | D3: 기술 교육 | E3: 46244 | F3: 46248 | G3: 2800000 | H3: 사전 승인완료
A4: 46227 | B4: FDC팀 | C4: 이영희 | D4: 현지 점검 | E4: 46237 | F4: 46240 | G4: 4100000
A5: 46234 | B5: 자동보정팀 | C5: 박민준 | D5: 부품 조달 | E5: 46249 | F5: 46252 | G5: 1000000
A6: 46234 | B6: FDC팀 | C6: 이영희 | D6: 후속 점검 | E6: 46250 | F6: 46253 | G6: 2000000
A7: 46241 | B7: 자동보정 | C7: 홍길동 | D7: 설비 협의 | E7: 46235 | F7: 46239 | G7: 3500000
A8: 46241 | B8: FDC DX | C8: 이영희 | D8: 현지 점검 | E8: 46237 | F8: 46240 | G8: 4100000

Sheet 품의출장_로그
A1: 기준일 | B1: 팀 | C1: 출장자 | D1: 출장목적 | E1: 출발일 | F1: 귀국일 | G1: 금액(원) | H1: 품의번호
A2: 46227 | B2: 자동보정팀 | C2: 홍길동 | D2: 설비 협의 | E2: 46235 | F2: 46239 | G2: 3500000 | H2: 2026-품의-0101
A3: 46227 | B3: FDC팀 | C3: 이영희 | D3: 현지 점검 | E3: 46237 | F3: 46240 | G3: 4100000 | H3: 2026-품의-0102
A4: 46241 | B4: 자동보정 | C4: 홍길동 | D4: 설비 협의 | E4: 46235 | F4: 46239 | G4: 3500000 | H4: 2026-품의-0201
A5: 46241 | B5: 제조DX솔루션 | C5: 김철수 | D5: 생산 점검 | E5: 46239 | F5: 46243 | G5: 2800000 | H5: 2026-품의-0202

Sheet 실집행_로그
A1: 기준일 | B1: 팀 | C1: 출장자 | D1: 출장목적 | E1: 출발일 | F1: 귀국일 | G1: 금액(원) | H1: 정산완료일
A2: 46227 | B2: 자동보정팀 | C2: 홍길동 | D2: 설비 협의 | E2: 46235 | F2: 46239 | G2: 3480000 | H2: 46246
A3: 46241 | B3: 자동보정 | C3: 홍길동 | D3: 설비 협의 | E3: 46235 | F3: 46239 | G3: 3480000 | H3: 46246
A4: 46241 | B4: 품질DX | C4: 이영희 | D4: 현지 점검 | E4: 46237 | F4: 46240 | G4: 4050000

Sheet 대시보드
B4: 이번주 기준일 | C4: 46241
B5: 지난주 기준일 | C5: 46234
